Workbook

Sheet Inputs
A1: Experiment inputs
A2: Edit the blue cells. The consumables, order-totals and cost sheets all recalculate from these.
A4: Parameter | B4: Value | D4: Basis | E4: Count | G4: Cost by scaling level | H4: Total cost ($)
A5: Samples | B5: 54 | D5: per sample | E5: =Inputs!$B$5 -> 54 | G5: per sample | H5: =SUMIFS(Pre_GEM_Consumables!$N$2:$N$102,Pre_GEM_Consumables!$E$2:$E$102,G5)+SUMIFS(Post_GEM_Consumables!$N$2:$N$97,Post_GEM_Consumables!$E$2:$E$97,G5) -> 751.55244
A6: Genetic pools | B6: 6 | D6: per genetic pool | E6: =Inputs!$B$6 -> 6 | G6: per genetic pool | H6: =SUMIFS(Pre_GEM_Consumables!$N$2:$N$102,Pre_GEM_Consumables!$E$2:$E$102,G6)+SUMIFS(Post_GEM_Consumables!$N$2:$N$97,Post_GEM_Consumables!$E$2:$E$97,G6) -> 819.26207
A7: Super-pools (combined stain/load units) | B7: 1 | D7: per super-pool | E7: =Inputs!$B$7 -> 1 | G7: per super-pool | H7: =SUMIFS(Pre_GEM_Consumables!$N$2:$N$102,Pre_GEM_Consumables!$E$2:$E$102,G7)+SUMIFS(Post_GEM_Consumables!$N$2:$N$97,Post_GEM_Consumables!$E$2:$E$97,G7) -> 6011.4482
A8: HTO batches (hashtag kits) | B8: 1 | D8: per HTO batch | E8: =Inputs!$B$8 -> 1 | G8: per lane | H8: =SUMIFS(Pre_GEM_Consumables!$N$2:$N$102,Pre_GEM_Consumables!$E$2:$E$102,G8)+SUMIFS(Post_GEM_Consumables!$N$2:$N$97,Post_GEM_Consumables!$E$2:$E$97,G8) -> 0
A9: Workers | B9: 3 | D9: per worker | E9: =Inputs!$B$9 -> 3 | G9: per worker | H9: =SUMIFS(Pre_GEM_Consumables!$N$2:$N$102,Pre_GEM_Consumables!$E$2:$E$102,G9)+SUMIFS(Post_GEM_Consumables!$N$2:$N$97,Post_GEM_Consumables!$E$2:$E$97,G9) -> 0
A10: GEM lanes / channels (generic) | B10: 8 | D10: per lane | E10: =Inputs!$B$10 -> 8 | G10: per run | H10: =SUMIFS(Pre_GEM_Consumables!$N$2:$N$102,Pre_GEM_Consumables!$E$2:$E$102,G10)+SUMIFS(Post_GEM_Consumables!$N$2:$N$97,Post_GEM_Consumables!$E$2:$E$97,G10) -> 0
A11: 5' GEM channels | B11: 8 | D11: per 5' GEM channel | E11: =Inputs!$B$11 -> 8 | G11: per 5' GEM channel | H11: =SUMIFS(Pre_GEM_Consumables!$N$2:$N$102,Pre_GEM_Consumables!$E$2:$E$102,G11)+SUMIFS(Post_GEM_Consumables!$N$2:$N$97,Post_GEM_Consumables!$E$2:$E$97,G11) -> 13743.368
A12: ATAC GEM channels | B12: 2 | D12: per ATAC GEM channel | E12: =Inputs!$B$12 -> 2 | G12: per 5'-GEX library | H12: =SUMIFS(Pre_GEM_Consumables!$N$2:$N$102,Pre_GEM_Consumables!$E$2:$E$102,G12)+SUMIFS(Post_GEM_Consumables!$N$2:$N$97,Post_GEM_Consumables!$E$2:$E$97,G12) -> 838.8997
A13: 5'-GEX libraries | B13: 8 | D13: per 5'-GEX library | E13: =Inputs!$B$13 -> 8 | G13: per 5'-VDJ library | H13: =SUMIFS(Pre_GEM_Consumables!$N$2:$N$102,Pre_GEM_Consumables!$E$2:$E$102,G13)+SUMIFS(Post_GEM_Consumables!$N$2:$N$97,Post_GEM_Consumables!$E$2:$E$97,G13) -> 1265.9806
A14: 5'-VDJ libraries | B14: 8 | D14: per 5'-VDJ library | E14: =Inputs!$B$14 -> 8 | G14: per 5'-ADT library | H14: =SUMIFS(Pre_GEM_Consumables!$N$2:$N$102,Pre_GEM_Consumables!$E$2:$E$102,G14)+SUMIFS(Post_GEM_Consumables!$N$2:$N$97,Post_GEM_Consumables!$E$2:$E$97,G14) -> 499.34238
A15: 5'-ADT libraries | B15: 8 | D15: per 5'-ADT library | E15: =Inputs!$B$15 -> 8 | G15: per ATAC library | H15: =SUMIFS(Pre_GEM_Consumables!$N$2:$N$102,Pre_GEM_Consumables!$E$2:$E$102,G15)+SUMIFS(Post_GEM_Consumables!$N$2:$N$97,Post_GEM_Consumables!$E$2:$E$97,G15) -> 3555.5977
A16: ATAC-ADT libraries | B16: 2 | D16: per ATAC-ADT library | E16: =Inputs!$B$16 -> 2 | G16: per ATAC-ADT library | H16: =SUMIFS(Pre_GEM_Consumables!$N$2:$N$102,Pre_GEM_Consumables!$E$2:$E$102,G16)+SUMIFS(Post_GEM_Consumables!$N$2:$N$97,Post_GEM_Consumables!$E$2:$E$97,G16) -> 25.049979
A17: ATAC libraries | B17: 2 | D17: per ATAC library | E17: =Inputs!$B$17 -> 2 | G17: per ATAC GEM channel | H17: =SUMIFS(Pre_GEM_Consumables!$N$2:$N$102,Pre_GEM_Consumables!$E$2:$E$102,G17)+SUMIFS(Post_GEM_Consumables!$N$2:$N$97,Post_GEM_Consumables!$E$2:$E$97,G17) -> 3542
A18: (fixed) | B18: 1 | D18: per run | E18: =Inputs!$B$18 -> 1 | G18: per Flex sample | H18: =SUMIFS(Pre_GEM_Consumables!$N$2:$N$102,Pre_GEM_Consumables!$E$2:$E$102,G18)+SUMIFS(Post_GEM_Consumables!$N$2:$N$97,Post_GEM_Consumables!$E$2:$E$97,G18) -> 0
G19: per Flex pool | H19: =SUMIFS(Pre_GEM_Consumables!$N$2:$N$102,Pre_GEM_Consumables!$E$2:$E$102,G19)+SUMIFS(Post_GEM_Consumables!$N$2:$N$97,Post_GEM_Consumables!$E$2:$E$97,G19) -> 0
A20: Default overage (extra to prepare) | B20: 0.1 | G20: per Flex library | H20: =SUMIFS(Pre_GEM_Consumables!$N$2:$N$102,Pre_GEM_Consumables!$E$2:$E$102,G20)+SUMIFS(Post_GEM_Consumables!$N$2:$N$97,Post_GEM_Consumables!$E$2:$E$97,G20) -> 0
A21: Flex v2 samples (fixation + hyb rxns) | B21: 0 | D21: per Flex sample | E21: =Inputs!$B$21 -> 0
A22: Flex v2 pools (GEM reactions) | B22: 0 | D22: per Flex pool | E22: =Inputs!$B$22 -> 0
A23: Flex v2 libraries | B23: 0 | D23: per Flex library | E23: =Inputs!$B$23 -> 0
A24: Flex v2 is an opt-in track: set the three counts above > 0 to include Flex reagents in totals (leave 0 for a 5'/ASAP/sort-only plan).

Sheet README
A1: Single-Cell Pipeline — Master Data Schema
A2: Tsang Lab | Draft schema for the experiment planning tool | Built from existing lab spreadsheets & protocols
A4: Tab color | B4: Meaning | C4: Who edits it | D4: How
A5: Red | B5: Admin-only — reference/pricing data | C5: PI, lab manager, or tool admin | D5: Lock the tab (Protect sheet / Protected ranges) in Google Sheets so only admins can edit
A6: Green | B6: Lab-editable — day-to-day updates | C6: Anyone in the lab | D6: Open editing, but structured as an append-only log where possible (see Inventory_Transactions)
A7: Purple | B7: Auto-computed / rarely touched | C7: No one manually — formulas or the tool write here | D7: Protect from manual edits; values come from formulas or the web app
A10: Sheet map
A11: Sheet | B11: Purpose | C11: Key column(s) | D11: Tier
A12: Kit_Catalog | B12: Every 10x kit/reagent: part numbers, kit size, price, reactions per kit | C12: kit_id (PK) | D12: Admin
A13: Antibody_HTO_Catalog | B13: TotalSeq HTO/ADT cocktails and hashtag antibodies | C13: item_id (PK) | D13: Admin
A14: Additional_Reagents_Catalog | B14: Third-party consumables (SPRI, ethanol, tips, QC kits, etc.) | C14: item_id (PK) | D14: Admin
A15: Per_Channel_Consumables | B15: How much SPRI/ethanol/EB each protocol needs per channel | C15: protocol (FK) | D15: Admin
A16: Sequencing_Pricing | B16: YCGA / external sequencing platform pricing | C16: platform_id (PK) | D16: Admin
A17: Modality_Definitions | B17: scRNAseq/CITEseq/ASAPseq/Flex definitions, required stages, default cell targets | C17: modality_id (PK) | D17: Admin
A18: Protocol_Stages | B18: Modular workflow building blocks (thaw, pool, stain, sort, stim, library prep...) | C18: stage_id (PK) | D18: Admin
A19: Stage_Reagent_Requirements | B19: Links each protocol stage to catalog items + amount per sample/channel/pool | C19: stage_id, item_id (FK) | D19: Admin
A20: Personnel_Roster | B20: Who can run which stage, current availability | C20: person_id (PK) | D20: Lab-editable
A21: Live_Inventory | B21: Current on-hand quantity per catalog item (computed from transactions) | C21: item_id (FK) | D21: Purple = auto-computed
A22: Inventory_Transactions | B22: Append-only log: every receipt or use of a reagent | C22: txn_id (PK) | D22: Lab-editable
A23: Experiment_Log | B23: Historical record of past experiments — plans, actuals, costs | C23: experiment_id (PK) | D23: Lab-editable
A26: Design principles
A27: 1. Catalog data (kits, pricing, protocols) is admin-locked — it changes rarely and errors here break every calculation downstream.
A28: 2. Inventory is NEVER edited by typing a new stock number directly. Everyone logs a transaction (+received / -used); Live_Inventory's stock column is a SUMIFS formula over the log. This avoids two people overwriting each other's edits and gives you a use history for free.
A29: 3. Every table has a stable *_id primary key so the future web app (and other sheets) can reference rows reliably even if names or prices change.
A30: 4. Protocol_Stages + Stage_Reagent_Requirements are the bridge between 'what modalities did you pick' and 'what do you need to order' — this is what replaces the fragmented one-off protocols.
A31: 5. This workbook is the template to recreate as a Google Sheets file (one tab = one sheet). Once migrated, use Data > Protected sheets and ranges to enforce the admin/lab-editable split.
A33: ARCHITECTURE NOTE (updated):
A34: Live inventory, inventory transactions, and the experiment log now live in the separate
A35: Live_Inventory workbook on Google Drive (single source of truth). This schema holds only
A36: reference data: catalogs, consumables recipes, pricing, modality/protocol definitions, and calculators.

Sheet Kit_Catalog
A1: Kit_Catalog
A2: Admin-only. Source: 10X_Reagent_Ordering_Tracker.xlsx (June 2026) + 10x Genomics official price list PDFs (verified 2026-07-01).
A4: kit_id | B4: chemistry | C4: category | D4: kit_name | E4: part_number | F4: kit_size | G4: reactions_per_kit | H4: price_usd | I4: price_verified_date | J4: price_source | K4: notes
A5: K001 | B5: 3' v4 | C5: GEX | D5: Chromium GEM-X Single Cell 3' Kit v4 | E5: PN-1000691 | F5: 16 rxn | G5: 16 | H5: 23670 | I5: unverified | J5: 10X_Reagent_Ordering_Tracker.xlsx (June 2026) - not in July 2026 price list export, unverified | K5: Includes GEM Kit, Gel Bead Kit, Dynabeads, LCK C.
A6: K002 | B6: 3' v4 | C6: GEX | D6: Chromium GEM-X Single Cell 3' Chip Kit v4 | E6: PN-1000690 | F6: 4 chips | G6: 16 | H6: 1250 | I6: unverified | J6: 10X_Reagent_Ordering_Tracker.xlsx (June 2026) - not in July 2026 price list export, unverified | K6: 16 (4 channels/chip).
A7: K003 | B7: 3' v4 | C7: Surface Protein | D7: Feature Barcode Kit v4 (3') | E7: PN-1000702 | F7: 16 rxn | G7: 16 | H7: 670 | I7: 2026-07-01 | J7: 10x Genomics store price list PDF (exported 2026-07-01)
A8: K004 | B8: 3' v4 | C8: Library | D8: Dual Index Kit NT, Set A | E8: PN-1000242 | F8: 96 rxn | G8: 96 | H8: 960 | I8: 2026-07-01 | J8: 10x Genomics store price list PDF (exported 2026-07-01) | K8: Cell-surface-protein library indices. Shared part: this same kit (PN-1000242) is also used as the Feature Barcode/Protein index kit for the 5' v3 OCM (multiplex) workflow - not a separate SKU, don't order twice.
A9: K005 | B9: 3' v4 OCM | C9: GEX | D9: GEM-X OCM 3' Chip Kit v4 4-plex (2 chips) | E9: PN-1000747 | F9: 2 chips | H9: 600 | I9: 2026-07-01 | J9: 10x Genomics store price list PDF (exported 2026-07-01) | K9: OCM hardware multiplexing chip for 3' chemistry.
A10: K006 | B10: 3' v4 OCM | C10: GEX | D10: GEM-X OCM 3' Chip Kit v4 4-plex (1 chip) | E10: PN-1000953 | F10: 1 chip | H10: 300 | I10: 2026-07-01 | J10: 10x Genomics store price list PDF (exported 2026-07-01)
A11: K007 | B11: 3' v4 OCM | C11: GEX | D11: GEM-X Universal 3' GEX v4 4-plex core reagents (16 samples) | E11: PN-1000779 | F11: 16 samp | G11: 16 | H11: 5994 | I11: 2026-07-01 | J11: 10x Genomics store price list PDF (exported 2026-07-01) | K11: Core reagents for OCM 4-plex workflow - pairs with K031/K032 chip.
A12: K008 | B12: 3' v4 OCM | C12: GEX | D12: GEM-X Universal 3' GEX v4 4-plex core reagents (8 samples) | E12: PN-1000957 | F12: 8 samp | G12: 8 | H12: 3994 | I12: 2026-07-01 | J12: 10x Genomics store price list PDF (exported 2026-07-01)
A13: K009 | B13: 5' v3 | C13: GEX | D13: Chromium GEM-X Single Cell 5' Kit v3 | E13: PN-1000699 | F13: 16 rxn | G13: 16 | H13: 23670 | I13: 2026-07-01 | J13: 10x Genomics store price list PDF (exported 2026-07-01) | K13: Core 5' assay. Includes Gel Beads, Dynabeads MyOne SILANE.
A14: K010 | B14: 5' v3 | C14: GEX | D14: Chromium GEM-X Single Cell 5' Kit v3 (4 rxn) | E14: PN-1000695 | F14: 4 rxn | G14: 4 | H14: 6498 | I14: 2026-07-01 | J14: 10x Genomics store price list PDF (exported 2026-07-01) | K14: Core 5' assay, small format.
A15: K011 | B15: 5' v3 | C15: GEX | D15: Chromium GEM-X Single Cell 5' Chip Kit | E15: PN-1000698 | F15: 4 chips | G15: 16 | H15: 1250 | I15: 2026-07-01 | J15: 10x Genomics store price list PDF (exported 2026-07-01) | K15: CORRECTED 2026-07-01: catalog previously listed this as PN-1000748 / 2 chips / $600, which is actually the OCM 4-plex chip variant, not the standard chip. Standard Chromium GEM-X Single Cell 5' Chip Kit v3 (4 chips, 16 channels) is PN-1000698, $1,250.
A16: K012 | B16: 5' v3 | C16: GEX/Library | D16: Library Construction Kit C | E16: PN-1000694 | F16: 16 rxn | G16: 16 | H16: 1250 | I16: 2026-07-01 | J16: 10x Genomics store price list PDF (exported 2026-07-01) | K16: Extra LCK C may be needed when building both V(D)J and 5' GEX libraries from same cDNA.
A17: K013 | B17: 5' v3 | C17: Library | D17: Dual Index Kit TT, Set A | E17: PN-1000215 | F17: 96 rxn | G17: 96 | H17: 960 | I17: 2026-07-01 | J17: 10x Genomics store price list PDF (exported 2026-07-01) | K17: Library indices (GEX).
A18: K014 | B18: 5' v3 | C18: V(D)J | D18: V(D)J Amplification Kit, Human TCR | E18: PN-1000252 | F18: 16 rxn | G18: 16 | H18: 360 | I18: 2026-07-01 | J18: 10x Genomics store price list PDF (exported 2026-07-01) | K18: Order kit matching species + chain.
A19: K015 | B19: 5' v3 | C19: V(D)J | D19: V(D)J Amplification Kit, Human BCR | E19: PN-1000253 | F19: 16 rxn | G19: 16 | H19: 360 | I19: 2026-07-01 | J19: 10x Genomics store price list PDF (exported 2026-07-01) | K19: Order kit matching species + chain.
A20: K016 | B20: 5' v3 | C20: Surface Protein | D20: Feature Barcode Kit v3 | E20: PN-1000703 | F20: 16 rxn | G20: 16 | H20: 670 | I20: 2026-07-01 | J20: 10x Genomics store price list PDF (exported 2026-07-01)
A21: K017 | B21: 5' v3 | C21: Library | D21: Dual Index Kit TN, Set A | E21: PN-1000250 | F21: 96 rxn | G21: 96 | H21: 960 | I21: 2026-07-01 | J21: 10x Genomics store price list PDF (exported 2026-07-01) | K21: Cell-surface-protein library indices.
A22: K018 | B22: 5' v3 | C22: CRISPR | D22: 5' CRISPR Kit | E22: PN-1000451 | F22: 16 rxn | G22: 16 | H22: 670 | I22: 2026-07-01 | J22: 10x Genomics store price list PDF (exported 2026-07-01)
A23: K019 | B23: 5' v3 | C23: GEX | D23: GEM-X Universal 5' GEX cDNA Kit v3, 16 samples | E23: PN-1000826 | F23: 16 samp | G23: 16 | H23: 22420 | I23: 2026-07-01 | J23: 10x Genomics store price list PDF (exported 2026-07-01) | K23: Optional standalone cDNA-only reagent format - alternative to the all-in-one core reagents kit (K001) if buying cDNA and gel bead/chip components separately.
A24: K020 | B24: 5' v3 | C24: GEX | D24: GEM-X Universal 5' GEX cDNA Kit v3, Automated, 16 samples | E24: PN-1000889 | F24: 16 samp | G24: 16 | H24: 23225 | I24: 2026-07-01 | J24: 10x Genomics store price list PDF (exported 2026-07-01) | K24: Automated-workflow version of K037.
A25: K021 | B25: 5' v3 | C25: GEX/Library | D25: Library Construction Kit C, Automated 24 rxns / Manual 32 rxns | E25: PN-1000774 | F25: 24-32 rxn | G25: 24 | H25: 2400 | I25: 2026-07-01 | J25: 10x Genomics store price list PDF (exported 2026-07-01) | K25: Higher-throughput alternative to K004 (16 rxn kit) - cheaper per-reaction at scale.
A26: K022 | B26: 5' v3 | C26: V(D)J | D26: V(D)J Amplification Kit, Mouse TCR | E26: PN-1000254 | F26: 16 rxn | G26: 16 | H26: 360 | I26: 2026-07-01 | J26: 10x Genomics store price list PDF (exported 2026-07-01) | K26: Mouse equivalent of K006 (Human TCR). Only needed for mouse studies.
A27: K023 | B27: 5' v3 | C27: V(D)J | D27: V(D)J Amplification Kit, Mouse BCR | E27: PN-1000255 | F27: 16 rxn | G27: 16 | H27: 360 | I27: 2026-07-01 | J27: 10x Genomics store price list PDF (exported 2026-07-01) | K27: Mouse equivalent of K007 (Human BCR). Only needed for mouse studies.
A28: K024 | B28: 5' v3 OCM | C28: GEX | D28: GEM-X OCM 5' Chip Kit v3 4-plex (2 chips) | E28: PN-1000748 | F28: 2 chips | H28: 600 | I28: 2026-07-01 | J28: 10x Genomics store price list PDF (exported 2026-07-01) | K28: On-Chip Multiplexing (OCM) chip - 10x's native hardware multiplexing, an alternative to hashtag-oligo pooling. NEW: not yet reflected in Modality_Definitions/Protocol_Stages.
A29: K025 | B29: 5' v3 OCM | C29: GEX | D29: GEM-X OCM 5' Chip Kit v3 4-plex (1 chip) | E29: PN-1000955 | F29: 1 chip | H29: 300 | I29: 2026-07-01 | J29: 10x Genomics store price list PDF (exported 2026-07-01) | K29: Smaller-format OCM chip.
A30: K026 | B30: 5' v3 OCM | C30: GEX | D30: GEM-X Universal 5' GEX v3 4-plex core reagents (16 samples) | E30: PN-1000780 | F30: 16 samp | G30: 16 | H30: 5994 | I30: 2026-07-01 | J30: 10x Genomics store price list PDF (exported 2026-07-01) | K30: Core reagents for OCM 4-plex workflow - pairs with K027/K028 chip.
A31: K027 | B31: 5' v3 OCM | C31: GEX | D31: GEM-X Universal 5' GEX v3 4-plex core reagents (8 samples) | E31: PN-1000956 | F31: 8 samp | G31: 8 | H31: 3994 | I31: 2026-07-01 | J31: 10x Genomics store price list PDF (exported 2026-07-01)
A32: K028 | B32: Any (nuclei-based) | C32: Sample Prep | D32: Nuclei Isolation Kit with RNase Inhibitor v2 | E32: PN-1001101 | F32: 16 rxn | G32: 16 | H32: 2500 | I32: 2026-07-01 | J32: 10x Genomics store price list PDF (exported 2026-07-01) | K32: Optional add-on for ATAC/Multiome or nuclei-based workflows. Also listed on both the standard and OCM/multiplex 5' kit pages - same part, usable with 5' v3 if starting from nuclei.
A33: K029 | B33: Any (nuclei-based) | C33: Sample Prep | D33: Chromium Nuclei Isolation Kit with RNase Inhibitor | E33: PN-1000494 | F33: 16 rxn | G33: 16 | H33: 2060 | I33: 2026-07-01 | J33: 10x Genomics store price list PDF (exported 2026-07-01) | K33: Older-format alternative to K035. Also appears on both 5' v3 kit pages (standard + OCM).
A34: K030 | B34: Epi ATAC v2 | C34: ATAC | D34: Chromium Next GEM Single Cell ATAC Kit v2 | E34: PN-1000390 | F34: 16 rxn | G34: 16 | H34: 25000 | I34: 2026-07-01 | J34: 10x Genomics store price list PDF (exported 2026-07-01) | K34: Core assay kit. Includes Dynabeads MyOne SILANE.
A35: K031 | B35: Epi ATAC v2 | C35: ATAC | D35: Chromium Next GEM Chip H Single Cell Kit | E35: PN-1000161 | F35: 48 rxn | G35: 48 | H35: 1800 | I35: 2026-07-01 | J35: 10x Genomics store price list PDF (exported 2026-07-01) | K35: Microfluidic chips + gaskets.
A36: K032 | B36: Epi ATAC v2 | C36: ATAC | D36: Chromium Next GEM Chip H Single Cell Kit (16 rxn) | E36: PN-1000162 | F36: 16 rxn | G36: 16 | H36: 620 | I36: 2026-07-01 | J36: 10x Genomics store price list PDF (exported 2026-07-01)
A37: K033 | B37: Epi ATAC v2 | C37: Library | D37: Single Index Kit N, Set A | E37: PN-1000212 | F37: 96 rxn | G37: 96 | H37: 960 | I37: 2026-07-01 | J37: 10x Genomics store price list PDF (exported 2026-07-01) | K37: ATAC library indices.
A38: K034 | B38: Epi Multiome | C38: Multiome | D38: GEM-X Epi Multiome Kit | E38: PN-1000979 | F38: 16 samp | G38: 16 | H38: 35500 | I38: 2026-07-01 | J38: 10x Genomics store price list PDF (exported 2026-07-01) | K38: Includes GEM, Amp, Gel Bead, Dynabeads, ATAC kits.
A39: K035 | B39: Epi Multiome | C39: Multiome | D39: GEM-X Epi Multiome Chip Kit | E39: PN-1000951 | F39: 4 chips | G39: 16 | H39: 1250 | I39: 2026-07-01 | J39: 10x Genomics store price list PDF (exported 2026-07-01)
A40: K036 | B40: Flex v2 | C40: GEX | D40: GEM-X Flex v2 Core Reagents (16 samp) | E40: PN-1000927 | F40: 16 samp | G40: 16 | H40: 10200 | I40: 2026-07-01 | J40: 10x Genomics store price list PDF (exported 2026-07-01) | K40: Fixation/quench/permeabilization reagents.
A41: K037 | B41: Flex v2 | C41: GEX | D41: GEM-X Flex v2 Core Reagents (96 samp) | E41: PN-1000928 | F41: 96 samp | G41: 96 | H41: 24480 | I41: 2026-07-01 | J41: 10x Genomics store price list PDF (exported 2026-07-01)
...

Sheet Additional_Supply_Catalog
A1: Additional_Supply_Catalog
A2: Admin-only. Third-party consumables. Source: 10X_Reagent_Ordering_Tracker.xlsx + Reagents list.xlsx
A4: item_id | B4: applies_to_protocol | C4: reagent | D4: vendor | E4: catalog_number | F4: notes | G4: Price | H4: Stock Size (Units) | I4: Stock Units | J4: last_purchase_date | K4: sourcing_note
A5: Reagents
A6: R001 | B6: ASAP-seq | C6: Sterile Water | D6: Fisher Sci- Stockroom | E6: 10977015 | G6: 13.86 | H6: 500 | I6: mL | K6: No purchase record found for 'Sterile Water' as a standalone item - likely sourced from a shared stockroom supply not tracked as an individual purchase, or made in-house (autoclaved). Recommend confirming with lab manager.
A7: R002 | B7: ASAP-seq, CITE-seq, Sort | C7: PBS | D7: Stockroom | E7: 10010-023 | G7: 19.02 | H7: 500 | I7: mL | J7: 2025-02-12 | K7: PBS 1X, pH 7.4. Price has been rising slightly across recent orders ($16.70 -> $19.02).
A8: R003 | B8: 5' Library Prep | C8: Ethanol, 200 proof anhydrous | D8: Millipore Sigma | E8: E7023-500ML | F8: Make fresh 80% day-of. | G8: 109 | H8: 500 | I8: mL | K8: No purchase record found for this exact catalog number (Millipore Sigma E7023-500ML). Closest recent related purchases are a different brand/grade: RPI Reagent Grade Ethanol 4L, $69.53-$80 (most recent 2025-02-25) - verify these are interchangeable for your protocol before substituting.
A9: R004 | B9: 5' Library Prep | C9: Buffer EB | D9: QIAGEN | E9: 19086 | F9: Elution buffer, summed across elution steps. | G9: 49.9 | H9: 250 | I9: mL | J9: 2025-11-22 | K9: Price stable ~$49-50 across last 2 orders (special order via stockroom).
A10: R005 | B10: 5' Library Prep | C10: SPRIselect Reagent Kit | D10: Beckman Coulter | E10: B23318 | F10: Size selection / cleanups. | G10: 1635.9 | H10: 60 | I10: mL | J10: 2025-04-08 | K10: Price has varied significantly across orders ($1,558-$1,669 range); most recent shown.
A11: R006 | B11: All | C11: Qubit dsDNA HS Assay kit | D11: Thermo | E11: Q32854 | F11: 500 samples | G11: 426.65 | H11: 500 | I11: sample | K11: No exact match for PN Q32854. Closest possible successor product found: 'QUBIT 1X dsDNA HS Assay Kit, 500 rxn' (PN Q33231), Fisher Scientific, $381.65, purchased 2024-04-17 - may be a renumbered version of this kit; verify before ordering. Existing values below left unchanged.
A12: R007 | B12: All | C12: TapeStation HS D1000. | D12: Agilent Technologies | E12: 5067-5584 (ScreenTape) + 5067-5585 (Reagents) + 5067-5587 (Ladder) | G12: 606.25 | H12: 1 | I12: kit | J12: 2025-04-08 | K12: Price = sum of most recent purchases of all 3 required TapeStation components (ScreenTape $398.67 + Reagents $135.80 + Ladder $71.78). Original catalog_number also listed 5067-4626, which is actually the Bioanalyzer HS DNA kit (different, older instrument) - not part of this TapeStation bundle. Lane/sample count per kit not specified in purchase record - verify with vendor.
A13: R008 | B13: All | C13: 10% Tween 20 | D13: Bio-Rad Laboratories | E13: 1662404 | F13: Component of Elution Solution I. | G13: 40.52 | H13: 5 | I13: mL | J13: 2024-01-08 | K13: Only 1 purchase record in history (Jan 2024) - consider reverifying current price before large orders.
A14: R009 | B14: All | C14: KAPA Library Quantification Kit | D14: Roche/KAPA | E14: KK4824 | K14: No purchase record found for KAPA Library Quantification Kit (KK4824) in the provided lab spend history - vendor/price below are carried over from the original tracker, unverified.
A15: R010 | B15: ASAP-seq | C15: 16% formaldehyde | D15: Life Technologies (special order) | E15: 28906 | G15: 47 | H15: 1000 | I15: uL | J15: 2024-06-01 | K15: Pierce 16% Formaldehyde, methanol-free. A 10-ampule pack of the same PN is also available for $62.25 total (~$6.23/mL) - cheaper per-mL if buying in bulk.
A16: R011 | B16: ASAP-seq | C16: 2M Glycine | D16: Thermo Fisher Scientific | E16: A13816.36 | G16: 46.2 | H16: 500 | I16: g | J16: 2024-01-08 | K16: Glycine, 99% - only 1 purchase record found.
A17: R012 | C17: IPEGAL
A18: R013 | C18: empty place
A19: R014 | B19: ASAP-seq | C19: 1uM Bridge Oligo | I19: uL | K19: No purchase record found for '1uM Bridge Oligo' - this is a custom/specialty oligo (likely made-to-order from IDT or similar), not something that would appear as a standard catalog purchase. Recommend sourcing directly from an oligo synthesis vendor.
A20: R015 | B20: CITE-seq, ASAP-seq | C20: ADT TotalseqA antibody cocktail | D20: BioLegend | E20: 399907 (TotalSeq-A) | G20: 4546.5 | H20: 5 | I20: vial | J20: 2025-01-09 | K20: ADT = TotalSeq Universal Cocktail, used for CITE-seq/ASAP-seq antibody-derived tags. TotalSeq-C (5 test) = $4,546.50 (2025-01-09); TotalSeq-A (5 test) = $4,878.00 (2025-04-03). Price shown is for the C version; use A version price if that's what the protocol calls for.
A21: R016 | B21: CITE-seq, ASAP-seq | C21: ADT TotalseqC antibody cocktail | D21: BioLegend | E21: 399905 (TotalSeq-C) | G21: 4546.5 | H21: 5 | I21: vial | J21: 2025-01-09 | K21: ADT = TotalSeq Universal Cocktail, used for CITE-seq/ASAP-seq antibody-derived tags. TotalSeq-C (5 test) = $4,546.50 (2025-01-09); TotalSeq-A (5 test) = $4,878.00 (2025-04-03). Price shown is for the C version; use A version price if that's what the protocol calls for.
A22: R017 | B22: CITE-seq, ASAP-seq, Sort | C22: HTO TotalseqA | D22: BioLegend | E22: e.g. 394661-394689 (TotalSeq-C0251-0265 Hashtags) | G22: 517 | H22: 20 | I22: uL
A23: R018 | B23: CITE-seq, ASAP-seq, Sort | C23: HTO TotalseqC | D23: BioLegend | E23: e.g. 394661-394689 (TotalSeq-C0251-0265 Hashtags) | G23: 517 | H23: 20 | I23: uL | J23: 2025-11-22 | K23: HTO = individual TotalSeq Hashtag antibody vials, one per pool/sample. Price is per hashtag vial (recent purchases of hashtags 3, 4, 5, 15 all priced at $517 each). Need one vial per pool - do not reuse a hashtag within a batch.
A24: R019 | B24: CITE-seq, ASAP-seq, Sort | C24: Human TruStain FcX (Fc block) | D24: BioLegend | E24: 422302 | F24: OR TruStain FcX PLUS at 2 uL/sample. | G24: 229 | H24: 1000 | I24: uL
A25: R020 | B25: ASAP-seq | C25: RPxx or D7xx | I25: uL | K25: No purchase record found for 'RPxx or D7xx' - these are typically Illumina/10x sample index primer names, not a separately purchased consumable (they usually come from the Dual Index Kit already in Kit_Catalog, e.g. K005/K009/K014). Recommend removing this row or cross-referencing Kit_Catalog instead.
A26: R021 | B26: ASAP-seq | C26: 1M Tris-HCl pH 7.5 | D26: Cayman Chemical Company | E26: 600201 | G26: 44 | H26: 250 | I26: mL | J26: 2023-08-01 | K26: 1M Tris-HCl, pH 7.5. Only 1 purchase record found (2023) - reverify current price, it's 3 years stale.
A27: R022 | B27: ASAP-seq | C27: 5M NaCl | D27: Santa Cruz Biotechnology | E27: sc-295832 | G27: 14.55 | H27: 1000 | I27: mL | J27: 2023-07-31 | K27: 5M/1M NaCl solution. Only 1 purchase record found (2023) - reverify current price.
A28: R023 | B28: ASAP-seq | C28: 1M MgCl2 | D28: Thermo Fisher Scientific | E28: AM9530G | G28: 57 | H28: 100 | I28: mL | J28: 2024-03-19 | K28: 1M MgCl2.
A29: R024 | B29: ASAP-seq | C29: NP40 | D29: Thermo Fisher Scientific | E29: J19628.AP | G29: 106 | H29: 500 | I29: mL | J29: 2024-01-10 | K29: Nonidet P40 Substitute (NP-40 equivalent) - only 1 purchase record found.
A30: R025 | B30: ASAP-seq | C30: 5% Digitonin | D30: Life Technologies | E30: BN2006 | G30: 124.65 | H30: 1 | I30: mL | J30: 2025-11-05 | K30: Digitonin (5% stock).
A31: R026 | B31: ASAP-seq, CITE-seq | C31: BSA (powder) | D31: VWR | E31: 0332-25g | G31: 103.8 | H31: 25 | I31: g | J31: 2023-08-17 | K31: 10% Bovine Serum Albumin, Aqueous, Nuclease-Free - best available match for '10% BSA'. Only 1 purchase record found (2023) - reverify current price. A different product, MACS BSA Stock Solution (Miltenyi, 130-091-376), was also purchased more recently (Jan 2024) if that's an acceptable substitute.
A32: R027 | B32: Thaw | C32: RPMI | D32: Various (stockroom) | E32: 11875-093 | F32: Thawing/wash media. | G32: 6.78 | H32: 500 | I32: mL | J32: 2026-07-01 | K32: RPMI +L-Glutamine - price has been very stable (~$6.24-6.78) across the last 2+ years.
A33: R028 | B33: Thaw | C33: HEPES | D33: Cayman Chemical Company | E33: 600212 | G33: 32 | H33: 100 | I33: mL | J33: 2023-08-01 | K33: 1M HEPES stock solution. Only 1 purchase record found (2023) - reverify current price.
A34: R029 | B34: Thaw | C34: DNase (stock 10 mg/mL) | D34: STEMCELL Technologies | E34: 07470 | F34: High conc. for thaw, low conc. after. | G34: 388 | H34: 100 | I34: mg | J34: 2026-04-20 | K34: DNase I - price has been completely stable at $388 across 6 recent orders.
A35: R030 | B35: Thaw | C35: APOI Dye | D35: Revvity | E35: CS2-0106-25ML | G35: 606 | H35: 25 | I35: mL | K35: No confident match found for 'APOI Dye' - likely a viability/live-dead stain but the exact product is unclear from this name. If this refers to a Zombie fixable viability dye, BioLegend's Zombie UV Fixable Viability Kit (PN 423108, ~$89-335 depending on pack size, most recent 2025-12-04) is the closest match in purchase history - please confirm the intended product.
A36: R031 | B36: Sort | C36: Flow Antibodies | K36: 'Flow Antibodies' is too generic to match to a single SKU - the specific antibody panel depends on which markers are being sorted for. Recommend listing each antibody as its own catalog row once the sort panel is finalized.
A37: R032 | B37: Thaw, Sort | C37: FBS | D37: Stockroom | E37: A5256801 | G37: 356.71 | H37: 500 | I37: mL | J37: 2024-09-16 | K37: FBS (value grade). A higher-grade alternative, BenchMark FBS (GeminiBio, 100-106-500), was purchased more recently in smaller volume history - compare grades before restocking.
A38: R033 | B38: Stim | C38: Stimulation Reagents/ treatments | K38: 'Stimulation Reagents/treatments' is condition-dependent - see the existing Immune_Cell_Stimulation... reference table for specific stimulant catalog numbers per assay; not matchable to one SKU here.
A39: R034 | B39: Bulk RNA | C39: Trizol | D39: Stockroom / Thermo Fisher Scientific | E39: 10296-010 | G39: 263.34 | H39: 100 | I39: mL | J39: 2025-03-07 | K39: TRIzol LS Reagent, 100 mL.
A41: R035 | B41: Flex v2 | C41: Formaldehyde 37% (Fisher BioReagents) | D41: Fisher Scientific | E41: BP531-25 | F41: Fisher BioReagents BP531-25, 25 mL. List ~$101.25 (Cole-Parmer, 2026) - verify institutional price. | G41: 101.25 | H41: 25 | I41: mL | K41: Flex Fixation Buffer B (60 uL/sample). Price not on file - VERIFY.
A42: R036 | B42: Flex v2 | C42: Glycerol, >=99% (mol. biology) | D42: Millipore Sigma | E42: G5516-100ML | F42: Sigma G5516-100ML, 100 mL. List ~$62.79 (Midland Sci, 2026) - verify institutional price. | G42: 62.79 | H42: 100 | I42: mL | K42: 50% glycerol for -80C storage / unused chip wells (CG000782/CG000834). Price not on file - VERIFY.
...

Sheet Cell Pooling Calculator
A1: Batch X
A2: # | B2: sample ID | C2: Visit | D2: Group | E2: Pool | F2: Live % | G2: Total Viable Cell Count (/mL) | H2: Vol. Dilute for count (mL) | I2: Total Viable Cells | J2: Cells pooled for sort | K2: Pool Volume (uL) -- sort | L2: Cells pooled for unsort | M2: Pool Volume (uL) -- unsort | N2: Cells to RNA | O2: Volume to RNA (uL)
A3: 1 | B3: 1006 | C3: V00 | D3: P | E3: 1 | F3: 0.9 | G3: 1370000 | H3: 2.3 | I3: 3150000 | J3: 1500000 | K3: 1094.89 | N3: 500000 | O3: 364.96

Sheet Modality_Definitions
A1: Modality_Definitions
A2: Admin-only. Source: Handbook_Setting up a Single Cell Experiment (Ayers/Benmelech). Drives which stages + kits a plan pulls in.
A4: modality_id | B4: modality | C4: chemistry | D4: required_stage_ids | E4: default_target_recovered_cells | F4: typical_doublet_rate | G4: notes
A5: M001 | B5: scRNAseq | C5: GEM-X 5' v3 | E5: 8000-10000 (single sample/channel) | F5: 7.6% at 10k | G5: Standard immune profiling.
A6: M002 | B6: CITEseq | C6: GEM-X 5' v3 | E6: 5000/sample if 4-plex (20000/channel) | F6: ~15% at 20k, mitigated by hashtag demux | G6: Adds ADT library; needs antibody panel + Fc block.
A7: M003 | B7: ASAPseq | C7: Epi ATAC (TotalSeq-A) | E7: 3000-5000 (FACS-enriched) | F7: Lower; enrichment reduces load needed | G7: Nuclei prep, Tn5 tagmentation - time sensitive.
A8: M004 | B8: VDJ (TCR/BCR) | C8: GEM-X GEM-X 5' v3 (add-on) | E8: N/A - derived from GEX cDNA | F8: N/A | G8: Needs enough T/B cells for clonal expansion (~250+ cells min.).
A9: M005 | B9: Cell sorting (FACS enrichment) | C9: N/A | E9: Depends on target population | F9: N/A | G9: ~0.5% of PBMCs for pDCs, e.g.; send more cells for rare populations.
A10: M006 | B10: In vitro stimulation | C10: N/A | E10: N/A | F10: N/A | G10: Reserve 100-500k cells/sample pre-stim; see Immune Cell Stimulation Assays Table.
A11: M007 | B11: Flex (fixed RNA profiling) | C11: Flex v2 | E11: 10000-27000/sample (no sort) | F11: Lower - probe-based, less doublet-sensitive | G11: Good for banked/fixed samples; different sample-prep track.

Sheet Protocol_Stages
A1: Protocol_Stages
A2: Admin-only. Modular building blocks replacing the fragmented per-experiment protocols. Source: in-progress Handbook + MADI/IDVax batch docs.
A4: stage_id | B4: stage_name | C4: stage_description | D4: typical_time_window | E4: personnel_rule | F4: prerequisite_stage_id | G4: source_protocol_doc | H4: notes
A5: ST1 | B5: thaw | C5: Cell thawing / PBMC prep & Pooling | D5: 7-10am | E5: 1 worker per ~18 samples | G5: PBMC_Isolation_120225_AAannotated.docx / Handbook | H5: Warm media 20 min ahead; centrifuge thaw 10 min @350g.
A6: ST2 | B6: hash | C6: Pool & hash (sample pooling, HTO labeling) | D6: Immediately after thaw | E6: 1 worker per ~27 samples | G6: Handbook Batch Organization section | H6: No 2 samples from same donor/related subject in one pool.
A7: ST3 | B7: CITE-seq | C7: CITE-seq antibody staining | D7: After pooling | E7: 1 dedicated worker | G7: CITE-seq Batch2 protocol - AJ.docx; CITEseq_protocol_full.pdf | H7: Fc block first; titrate antibody panel in advance.
A8: ST4 | B8: ASAP-seq | C8: ASAP-seq nuclei prep / tagmentation | D8: After pooling, parallel to ST3 | E8: 1 dedicated worker | G8: ASAP_protocol_CHI.pdf | H8: Time-sensitive Tn5 step - do not delay.
A9: ST5 | B9: sort | C9: Cell sorting (FACS) | D9: Parallel to ST3/ST4 | E9: 1 dedicated worker + Flow Core slot | G9: Handbook Hoods/sorter section | H9: Book Yale Flow Core in advance; separate sort vs. unsort tubes.
A10: ST6 | B10: 5'-GEM | C10: 5' GEM generation & loading | D10: After staining/sorting complete | E10: 1-2 workers | G10: 10x user guides (CG000733 etc.) | H10: Superload per lab convention (skip water dilution step).
A11: ST7 | B11: ATAC-GEM | C11: Epi ATAC GEM generation & loading
A12: ST8 | B12: 5'-GEX | C12: 5' GEX Library construction & QC | D12: Days 1-5 post GEM | E12: 1-2 workers, ~1 week | G12: 10x user guides; SPRIselect User Guide | H12: cDNA QC -> library construction -> library QC -> submit to YCGA.
A13: ST9 | B13: 5'-VDJ | C13: 5' V(D)J Library Construction
A14: ST10 | B14: 5'-ADT | C14: 5' ADT Library Construction
A15: ST11 | B15: ATAC-ADT | C15: Epi ATAC ADT Library Construction
A16: ST12 | B16: ATAC | C16: Epi ATAC Library Construction
A17: ST13 | B17: stim | C17: In vitro stimulation assay | D17: Parallel track, separate reserved cells | E17: 1 worker | G17: Immune Cell Stimulation Assays Table.xlsx | H17: Reserve leftover cells after pooling; assay per stim condition chosen.
A18: ST14 | B18: Bulk-RNA | C18: Bulk RNA (Trizol) reserve | D18: After pooling, opportunistic | E18: 1-2 workers | G18: Trizol RNA Isolation SOP.pdf | H18: Reserve 100-500k leftover cells per sample.
A19: ST15 | B19: sequence | C19: Sequencing submission (YCGA) | D19: After library QC | E19: 1 worker | G19: YCGA submission.docx | H19: Submit via iLAB; confirm grant to charge with lab manager.
A20: ST16 | C20: Flex fixation / sample prep | D20: Pre-experiment or day-of (fixed samples) | E20: 1-2 workers | G20: GEM-X Flex v2 protocols (CG000833/834/835) | H20: Different track from live-cell thaw; can be banked ahead of time.

Sheet Sequencing_Pricing
A1: Sequencing_Pricing
A2: Admin-only. Source: Sequencing Options and Pricing.xlsx (2025/2026 quotes). Refresh yearly.
A4: platform_id | B4: platform | C4: configuration | D4: price_usd | E4: price_per_M_reads | F4: reads | G4: max_cycles | H4: notes
A5: S001 | B5: Nextseq 2000 (YCGA) | C5: 50c P4 | D5: 1800 | E5: 1 | F5: 1.8B | G5: 88 | H5: Walk-up, requires iLAB reservation + training.
A6: S002 | B6: Nextseq 2000 (YCGA) | C6: 100c P4 | D6: 2160 | E6: 1.46 | G6: 138
A7: S003 | B7: Nextseq 2000 (YCGA) | C7: 100c P3 | D7: 1515.8 | E7: 1.61 | F7: 1.2B | G7: 138
A8: S004 | B8: Nextseq 2000 (YCGA) | C8: 100c P2 | D8: 982.8 | E8: 3.15 | F8: 400M | G8: 138
A9: S005 | B9: Novaseq (YCGA) | C9: 2x150 group flowcell | E9: 1.049 | G9: 338 | H9: Purchase by # reads; pooled with other labs. + $25/sample QC.
A10: S006 | B10: Novaseq (YCGA) | C10: SP 2x150 (full flowcell) | D10: 2617 | E10: 3.27 | F10: 650-800M | H10: Purchase entire flowcell. + $25/sample QC.
A11: S007 | B11: MiSeq (YCGA) | C11: 500c | D11: 1905 | E11: 76.2 | F11: 22-25M | G11: 529 | H11: Purchase entire flowcell. + $25/sample QC.
A12: S008 | B12: Aviti (YCGA) | C12: 2x150 High Output | D12: 2856 | E12: 2.86 | F12: 1B | H12: + $25/sample QC.
A13: S009 | B13: Nanopore MinION | C13: Long read | D13: 800 | F13: 48Gb | H13: Available in Chung Lab; reagents extra.
A14: S010 | B14: Ultima (Novogene, external) | C14: 300bp single end | D14: 3499 | E14: 0.35 | F14: 10B | H14: V(D)J library sequencing NOT supported.

Sheet Personnel_Roster
A1: Personnel_Roster
A2: Lab-editable. Replace example rows with your real roster. trained_stage_ids references Protocol_Stages (comma-separated).
A4: person_id | B4: name | C4: role | D4: trained_stage_ids | E4: weekly_availability | F4: active | G4: notes
A5: P001 | B5: Example: Person A | C5: Grad student | D5: ST1,ST2,ST6,ST7 | E5: Mon/Wed/Fri | F5: Yes | G5: EXAMPLE ROW - replace with real roster
A6: P002 | B6: Example: Person B | C6: Research assistant | D6: ST1,ST3,ST6 | E6: Tue/Thu | F6: Yes | G6: EXAMPLE ROW - replace with real roster
A7: P003 | B7: Example: Person C | C7: Postdoc | D7: ST4,ST5,ST8 | E7: Flexible | F7: Yes | G7: EXAMPLE ROW - replace with real roster

Sheet Cell_Flow_Assumptions
A1: Cell_Flow_Assumptions
A2: Editable cell-count assumptions for the cell-flow diagram (planner Workflow tab). Edit default_value cells and re-upload; keep assumption_id and column headers unchanged.
A4: assumption_id | B4: label | C4: default_value | D4: units | E4: notes
A5: cells_per_sample_start | B5: Assumed cells available per sample | C5: 5000000 | D5: cells/sample | E5: Context only; the pooling take is fixed regardless of a sample’s actual count.
A6: cells_per_sample_pooling | B6: Cells taken per sample for pooling (CITE-seq staining input) | C6: 1500000 | D6: cells/sample | E6: Fixed amount added from each sample into its genetic pool, regardless of how many cells the sample had.
A7: cells_per_sample_bulk | B7: Cells reserved per sample for bulk RNA-seq | C7: 500000 | D7: cells/sample | E7: Set aside per sample (Trizol) for bulk RNA-seq. Required when pooling, for SNP demux.
A8: cells_per_sample_bulk_low | B8: Minimum bulk reserve for low-count samples | C8: 100000 | D8: cells/sample | E8: Floor for samples that don’t have enough to spare the full bulk reserve.
A9: cells_per_sample_stim | B9: Extra cells reserved per sample for stim | C9: 200000 | D9: cells/sample | E9: Saved per sample for the stim track.
A10: cells_per_pool_load | B10: Cells taken from each genetic pool per non-sort droplet load | C10: 1200000 | D10: cells/pool | E10: 1.2M/pool for unsort & ASAP; each per-pool tube HTO-stained (TotalSeq-C for CITE, TotalSeq-A for ASAP). Sort takes the remainder.
A11: cells_for_panel_stain | B11: Cells subsampled from the combined pool for surface-panel staining | C11: 1500000 | D11: cells/load | E11: After per-pool tubes combine, 1.5M taken for lyo-panel staining (3 vials).
A12: cells_at_load | B12: Target cells at loading / transposition | C12: 1200000 | D12: cells/load | E12: Super-load target after panel-stain washes (~1.1–1.2M).
A13: allcells_control_fraction | B13: ALLCELLS control added per pool (fraction of pooled cells) | C13: 0.25 | D13: fraction | E13: Leukopak ALLCELLS spike-in per pool (~25%). Set 0 to exclude.

Sheet Pre_GEM_Consumables
A1: Section | B1: Type | C1: Item / supply | D1: Item ID | E1: Scaling basis | F1: Amount per unit | G1: Unit | H1: Overage | I1: Count (x) | J1: Total needed | K1: Order (rounded) | L1: Unit price ($) | M1: Cost per basis-unit ($) | N1: Total cost ($) | O1: Notes | P1: _price | Q1: _stock | R1: _stockUnit
A2: II. PBMC prep | B2: BUFFER ▸ prepare | C2: RPMI-DNase (thaw media) | E2: (prep total) | G2: mL | J2: =(12*Inputs!$B$5)*(1+Inputs!$B$20) -> 712.8 | O2: Standard-recipe volume to prepare; costed components are the item rows below (see Buffer recipes).
A3: II. PBMC prep | B3: BUFFER ▸ prepare | C3: RPMI-DNase-low | E3: (prep total) | G3: mL | J3: =(50*Inputs!$B$9)*(1+Inputs!$B$20) -> 165 | O3: Standard-recipe volume to prepare; costed components are the item rows below (see Buffer recipes).
A4: II. PBMC prep | B4: Item | C4: 15mL conical | D4: S006 | E4: per sample | F4: 1 | G4: tube | H4: =Inputs!$B$20 -> 0.1 | I4: =VLOOKUP(E4,Inputs!$D$5:$E$23,2,FALSE()) -> 54 | J4: =F4*I4*(1+H4) -> 59.4 | K4: =IF(ISNUMBER(MATCH(G4,{"tube","each","plate","vial","kit","bottle","aliquot","strainer","cap","lane-rxn","tip","strip","lane","channel","library","sample"},0)),ROUNDUP(J4,0),ROUND(J4,2)) -> 60 | L4: =IFERROR(IF(OR(D4="",P4="",Q4="",Q4=0),"",IF(VLOOKUP(R4,Unit_Conversions!$A$5:$C$28,3,FALSE())=VLOOKUP(G4,Unit_Conversions!$A$5:$C$28,3,FALSE()),P4*VLOOKUP(G4,Unit_Conversions!$A$5:$C$28,2,FALSE())/(Q4*VLOOKUP(R4,Unit_Conversions!$A$5:$C$28,2,FALSE())),"")),"") -> 0.2222 | M4: =IFERROR(F4*L4,"") -> 0.2222 | N4: =IFERROR(J4*L4,"") -> 13.19868 | O4: [no catalog price] | P4: =IFERROR(IF(LEFT(D4,1)="K",VLOOKUP(D4,Kit_Catalog!$A:$K,8,FALSE()),VLOOKUP(D4,Additional_Supply_Catalog!$A:$K,7,FALSE())),"") -> 11.11 | Q4: =IFERROR(IF(LEFT(D4,1)="K",VLOOKUP(D4,Kit_Catalog!$A:$K,7,FALSE()),VLOOKUP(D4,Additional_Supply_Catalog!$A:$K,8,FALSE())),"") -> 50 | R4: =IFERROR(IF(LEFT(D4,1)="K","rxn",VLOOKUP(D4,Additional_Supply_Catalog!$A:$K,9,FALSE())),"") -> tube
A5: II. PBMC prep | B5: Item | C5: Nexcelom counting plate (24 samples/plate) | D5: S009 | E5: per sample | F5: 0.041667 | G5: plate | H5: =Inputs!$B$20 -> 0.1 | I5: =VLOOKUP(E5,Inputs!$D$5:$E$23,2,FALSE()) -> 54 | J5: =F5*I5*(1+H5) -> 2.4750198 | K5: =IF(ISNUMBER(MATCH(G5,{"tube","each","plate","vial","kit","bottle","aliquot","strainer","cap","lane-rxn","tip","strip","lane","channel","library","sample"},0)),ROUNDUP(J5,0),ROUND(J5,2)) -> 3 | L5: =IFERROR(IF(OR(D5="",P5="",Q5="",Q5=0),"",IF(VLOOKUP(R5,Unit_Conversions!$A$5:$C$28,3,FALSE())=VLOOKUP(G5,Unit_Conversions!$A$5:$C$28,3,FALSE()),P5*VLOOKUP(G5,Unit_Conversions!$A$5:$C$28,2,FALSE())/(Q5*VLOOKUP(R5,Unit_Conversions!$A$5:$C$28,2,FALSE())),"")),"") -> 25.535 | M5: =IFERROR(F5*L5,"") -> 1.0639668 | N5: =IFERROR(J5*L5,"") -> 63.199631 | O5: [no catalog price] | P5: =IFERROR(IF(LEFT(D5,1)="K",VLOOKUP(D5,Kit_Catalog!$A:$K,8,FALSE()),VLOOKUP(D5,Additional_Supply_Catalog!$A:$K,7,FALSE())),"") -> 5107 | Q5: =IFERROR(IF(LEFT(D5,1)="K",VLOOKUP(D5,Kit_Catalog!$A:$K,7,FALSE()),VLOOKUP(D5,Additional_Supply_Catalog!$A:$K,8,FALSE())),"") -> 200 | R5: =IFERROR(IF(LEFT(D5,1)="K","rxn",VLOOKUP(D5,Additional_Supply_Catalog!$A:$K,9,FALSE())),"") -> plate
A6: II. PBMC prep | B6: Item | C6: Thawsome | D6: S010 | E6: per sample | F6: 1 | G6: sample | H6: =Inputs!$B$20 -> 0.1 | I6: =VLOOKUP(E6,Inputs!$D$5:$E$23,2,FALSE()) -> 54 | J6: =F6*I6*(1+H6) -> 59.4 | K6: =IF(ISNUMBER(MATCH(G6,{"tube","each","plate","vial","kit","bottle","aliquot","strainer","cap","lane-rxn","tip","strip","lane","channel","library","sample"},0)),ROUNDUP(J6,0),ROUND(J6,2)) -> 60 | L6: =IFERROR(IF(OR(D6="",P6="",Q6="",Q6=0),"",IF(VLOOKUP(R6,Unit_Conversions!$A$5:$C$28,3,FALSE())=VLOOKUP(G6,Unit_Conversions!$A$5:$C$28,3,FALSE()),P6*VLOOKUP(G6,Unit_Conversions!$A$5:$C$28,2,FALSE())/(Q6*VLOOKUP(R6,Unit_Conversions!$A$5:$C$28,2,FALSE())),"")),"") -> 3.9 | M6: =IFERROR(F6*L6,"") -> 3.9 | N6: =IFERROR(J6*L6,"") -> 231.66 | O6: [no catalog price] | P6: =IFERROR(IF(LEFT(D6,1)="K",VLOOKUP(D6,Kit_Catalog!$A:$K,8,FALSE()),VLOOKUP(D6,Additional_Supply_Catalog!$A:$K,7,FALSE())),"") -> 195 | Q6: =IFERROR(IF(LEFT(D6,1)="K",VLOOKUP(D6,Kit_Catalog!$A:$K,7,FALSE()),VLOOKUP(D6,Additional_Supply_Catalog!$A:$K,8,FALSE())),"") -> 50 | R6: =IFERROR(IF(LEFT(D6,1)="K","rxn",VLOOKUP(D6,Additional_Supply_Catalog!$A:$K,9,FALSE())),"") -> each
A7: II. PBMC prep | B7: Item | C7: RPMI (mL) | D7: R027 | E7: per sample | F7: 13.2 | G7: mL | H7: =Inputs!$B$20 -> 0.1 | I7: =VLOOKUP(E7,Inputs!$D$5:$E$23,2,FALSE()) -> 54 | J7: =J2+J3 -> 877.8 | K7: =IF(ISNUMBER(MATCH(G7,{"tube","each","plate","vial","kit","bottle","aliquot","strainer","cap","lane-rxn","tip","strip","lane","channel","library","sample"},0)),ROUNDUP(J7,0),ROUND(J7,2)) -> 877.8 | L7: =IFERROR(IF(OR(D7="",P7="",Q7="",Q7=0),"",IF(VLOOKUP(R7,Unit_Conversions!$A$5:$C$28,3,FALSE())=VLOOKUP(G7,Unit_Conversions!$A$5:$C$28,3,FALSE()),P7*VLOOKUP(G7,Unit_Conversions!$A$5:$C$28,2,FALSE())/(Q7*VLOOKUP(R7,Unit_Conversions!$A$5:$C$28,2,FALSE())),"")),"") -> 0.01356 | M7: =IFERROR(F7*L7,"") -> 0.178992 | N7: =IFERROR(J7*L7,"") -> 11.902968 | O7: RPMI base for both media: thaw (J2) + low (J3). 1 mL RPMI per mL media. | P7: =IFERROR(IF(LEFT(D7,1)="K",VLOOKUP(D7,Kit_Catalog!$A:$K,8,FALSE()),VLOOKUP(D7,Additional_Supply_Catalog!$A:$K,7,FALSE())),"") -> 6.78 | Q7: =IFERROR(IF(LEFT(D7,1)="K",VLOOKUP(D7,Kit_Catalog!$A:$K,7,FALSE()),VLOOKUP(D7,Additional_Supply_Catalog!$A:$K,8,FALSE())),"") -> 500 | R7: =IFERROR(IF(LEFT(D7,1)="K","rxn",VLOOKUP(D7,Additional_Supply_Catalog!$A:$K,9,FALSE())),"") -> mL
A8: II. PBMC prep | B8: Item | C8: HEPES | D8: R028 | E8: per sample | F8: 0.3 | G8: mL | H8: =Inputs!$B$20 -> 0.1 | I8: =VLOOKUP(E8,Inputs!$D$5:$E$23,2,FALSE()) -> 54 | J8: =F8*I8*(1+H8) -> 17.82 | K8: =IF(ISNUMBER(MATCH(G8,{"tube","each","plate","vial","kit","bottle","aliquot","strainer","cap","lane-rxn","tip","strip","lane","channel","library","sample"},0)),ROUNDUP(J8,0),ROUND(J8,2)) -> 17.82 | L8: =IFERROR(IF(OR(D8="",P8="",Q8="",Q8=0),"",IF(VLOOKUP(R8,Unit_Conversions!$A$5:$C$28,3,FALSE())=VLOOKUP(G8,Unit_Conversions!$A$5:$C$28,3,FALSE()),P8*VLOOKUP(G8,Unit_Conversions!$A$5:$C$28,2,FALSE())/(Q8*VLOOKUP(R8,Unit_Conversions!$A$5:$C$28,2,FALSE())),"")),"") -> 0.32 | M8: =IFERROR(F8*L8,"") -> 0.096 | N8: =IFERROR(J8*L8,"") -> 5.7024 | P8: =IFERROR(IF(LEFT(D8,1)="K",VLOOKUP(D8,Kit_Catalog!$A:$K,8,FALSE()),VLOOKUP(D8,Additional_Supply_Catalog!$A:$K,7,FALSE())),"") -> 32 | Q8: =IFERROR(IF(LEFT(D8,1)="K",VLOOKUP(D8,Kit_Catalog!$A:$K,7,FALSE()),VLOOKUP(D8,Additional_Supply_Catalog!$A:$K,8,FALSE())),"") -> 100 | R8: =IFERROR(IF(LEFT(D8,1)="K","rxn",VLOOKUP(D8,Additional_Supply_Catalog!$A:$K,9,FALSE())),"") -> mL
A9: II. PBMC prep | B9: Item | C9: Dnase | D9: R029 | E9: per sample | F9: 1.05 | G9: mg | H9: =Inputs!$B$20 -> 0.1 | I9: =VLOOKUP(E9,Inputs!$D$5:$E$23,2,FALSE()) -> 54 | J9: =J2*0.1+J3*0.025 -> 75.405 | K9: =IF(ISNUMBER(MATCH(G9,{"tube","each","plate","vial","kit","bottle","aliquot","strainer","cap","lane-rxn","tip","strip","lane","channel","library","sample"},0)),ROUNDUP(J9,0),ROUND(J9,2)) -> 75.41 | L9: =IFERROR(IF(OR(D9="",P9="",Q9="",Q9=0),"",IF(VLOOKUP(R9,Unit_Conversions!$A$5:$C$28,3,FALSE())=VLOOKUP(G9,Unit_Conversions!$A$5:$C$28,3,FALSE()),P9*VLOOKUP(G9,Unit_Conversions!$A$5:$C$28,2,FALSE())/(Q9*VLOOKUP(R9,Unit_Conversions!$A$5:$C$28,2,FALSE())),"")),"") -> 3.88 | M9: =IFERROR(L9,"") -> 3.88 | N9: =IFERROR(J9*L9,"") -> 292.5714 | O9: DNase from RPMI-DNase media: thaw 0.1 mg/mL + low 0.025 mg/mL (10 mg/mL stock at recipe dilution). | P9: =IFERROR(IF(LEFT(D9,1)="K",VLOOKUP(D9,Kit_Catalog!$A:$K,8,FALSE()),VLOOKUP(D9,Additional_Supply_Catalog!$A:$K,7,FALSE())),"") -> 388 | Q9: =IFERROR(IF(LEFT(D9,1)="K",VLOOKUP(D9,Kit_Catalog!$A:$K,7,FALSE()),VLOOKUP(D9,Additional_Supply_Catalog!$A:$K,8,FALSE())),"") -> 100 | R9: =IFERROR(IF(LEFT(D9,1)="K","rxn",VLOOKUP(D9,Additional_Supply_Catalog!$A:$K,9,FALSE())),"") -> mg
A10: II. PBMC prep | B10: Item | C10: APOI Dye | D10: R030 | E10: per sample | F10: 20 | G10: uL | H10: =Inputs!$B$20 -> 0.1 | I10: =VLOOKUP(E10,Inputs!$D$5:$E$23,2,FALSE()) -> 54 | J10: =F10*I10*(1+H10) -> 1188 | K10: =IF(ISNUMBER(MATCH(G10,{"tube","each","plate","vial","kit","bottle","aliquot","strainer","cap","lane-rxn","tip","strip","lane","channel","library","sample"},0)),ROUNDUP(J10,0),ROUND(J10,2)) -> 1188 | L10: =IFERROR(IF(OR(D10="",P10="",Q10="",Q10=0),"",IF(VLOOKUP(R10,Unit_Conversions!$A$5:$C$28,3,FALSE())=VLOOKUP(G10,Unit_Conversions!$A$5:$C$28,3,FALSE()),P10*VLOOKUP(G10,Unit_Conversions!$A$5:$C$28,2,FALSE())/(Q10*VLOOKUP(R10,Unit_Conversions!$A$5:$C$28,2,FALSE())),"")),"") -> 0.02424 | M10: =IFERROR(F10*L10,"") -> 0.4848 | N10: =IFERROR(J10*L10,"") -> 28.79712 | O10: [no catalog price] | P10: =IFERROR(IF(LEFT(D10,1)="K",VLOOKUP(D10,Kit_Catalog!$A:$K,8,FALSE()),VLOOKUP(D10,Additional_Supply_Catalog!$A:$K,7,FALSE())),"") -> 606 | Q10: =IFERROR(IF(LEFT(D10,1)="K",VLOOKUP(D10,Kit_Catalog!$A:$K,7,FALSE()),VLOOKUP(D10,Additional_Supply_Catalog!$A:$K,8,FALSE())),"") -> 25 | R10: =IFERROR(IF(LEFT(D10,1)="K","rxn",VLOOKUP(D10,Additional_Supply_Catalog!$A:$K,9,FALSE())),"") -> mL
A11: II. PBMC prep | B11: Item | C11: 50mL conical | D11: S007 | E11: per genetic pool | F11: 1 | G11: tube | H11: =Inputs!$B$20 -> 0.1 | I11: =VLOOKUP(E11,Inputs!$D$5:$E$23,2,FALSE()) -> 6 | J11: =F11*I11*(1+H11) -> 6.6 | K11: =IF(ISNUMBER(MATCH(G11,{"tube","each","plate","vial","kit","bottle","aliquot","strainer","cap","lane-rxn","tip","strip","lane","channel","library","sample"},0)),ROUNDUP(J11,0),ROUND(J11,2)) -> 7 | L11: =IFERROR(IF(OR(D11="",P11="",Q11="",Q11=0),"",IF(VLOOKUP(R11,Unit_Conversions!$A$5:$C$28,3,FALSE())=VLOOKUP(G11,Unit_Conversions!$A$5:$C$28,3,FALSE()),P11*VLOOKUP(G11,Unit_Conversions!$A$5:$C$28,2,FALSE())/(Q11*VLOOKUP(R11,Unit_Conversions!$A$5:$C$28,2,FALSE())),"")),"") -> 0.244 | M11: =IFERROR(F11*L11,"") -> 0.244 | N11: =IFERROR(J11*L11,"") -> 1.6104 | O11: [no catalog price] | P11: =IFERROR(IF(LEFT(D11,1)="K",VLOOKUP(D11,Kit_Catalog!$A:$K,8,FALSE()),VLOOKUP(D11,Additional_Supply_Catalog!$A:$K,7,FALSE())),"") -> 6.1 | Q11: =IFERROR(IF(LEFT(D11,1)="K",VLOOKUP(D11,Kit_Catalog!$A:$K,7,FALSE()),VLOOKUP(D11,Additional_Supply_Catalog!$A:$K,8,FALSE())),"") -> 25 | R11: =IFERROR(IF(LEFT(D11,1)="K","rxn",VLOOKUP(D11,Additional_Supply_Catalog!$A:$K,9,FALSE())),"") -> tube
A12: II. PBMC prep | B12: Item | C12: 50mL conical | D12: S007 | E12: per super-pool | F12: 1 | G12: tube | H12: =Inputs!$B$20 -> 0.1 | I12: =VLOOKUP(E12,Inputs!$D$5:$E$23,2,FALSE()) -> 1 | J12: =F12*I12*(1+H12) -> 1.1 | K12: =IF(ISNUMBER(MATCH(G12,{"tube","each","plate","vial","kit","bottle","aliquot","strainer","cap","lane-rxn","tip","strip","lane","channel","library","sample"},0)),ROUNDUP(J12,0),ROUND(J12,2)) -> 2 | L12: =IFERROR(IF(OR(D12="",P12="",Q12="",Q12=0),"",IF(VLOOKUP(R12,Unit_Conversions!$A$5:$C$28,3,FALSE())=VLOOKUP(G12,Unit_Conversions!$A$5:$C$28,3,FALSE()),P12*VLOOKUP(G12,Unit_Conversions!$A$5:$C$28,2,FALSE())/(Q12*VLOOKUP(R12,Unit_Conversions!$A$5:$C$28,2,FALSE())),"")),"") -> 0.244 | M12: =IFERROR(F12*L12,"") -> 0.244 | N12: =IFERROR(J12*L12,"") -> 0.2684 | O12: [no catalog price] | P12: =IFERROR(IF(LEFT(D12,1)="K",VLOOKUP(D12,Kit_Catalog!$A:$K,8,FALSE()),VLOOKUP(D12,Additional_Supply_Catalog!$A:$K,7,FALSE())),"") -> 6.1 | Q12: =IFERROR(IF(LEFT(D12,1)="K",VLOOKUP(D12,Kit_Catalog!$A:$K,7,FALSE()),VLOOKUP(D12,Additional_Supply_Catalog!$A:$K,8,FALSE())),"") -> 25 | R12: =IFERROR(IF(LEFT(D12,1)="K","rxn",VLOOKUP(D12,Additional_Supply_Catalog!$A:$K,9,FALSE())),"") -> tube
A13: II. PBMC prep | B13: Item | C13: ALLCELLS control aliquot | E13: per genetic pool | F13: 1 | G13: aliquot | H13: =Inputs!$B$20 -> 0.1 | I13: =VLOOKUP(E13,Inputs!$D$5:$E$23,2,FALSE()) -> 6 | J13: =F13*I13*(1+H13) -> 6.6 | K13: =IF(ISNUMBER(MATCH(G13,{"tube","each","plate","vial","kit","bottle","aliquot","strainer","cap","lane-rxn","tip","strip","lane","channel","library","sample"},0)),ROUNDUP(J13,0),ROUND(J13,2)) -> 7 | L13: =IFERROR(IF(OR(D13="",P13="",Q13="",Q13=0),"",IF(VLOOKUP(R13,Unit_Conversions!$A$5:$C$28,3,FALSE())=VLOOKUP(G13,Unit_Conversions!$A$5:$C$28,3,FALSE()),P13*VLOOKUP(G13,Unit_Conversions!$A$5:$C$28,2,FALSE())/(Q13*VLOOKUP(R13,Unit_Conversions!$A$5:$C$28,2,FALSE())),"")),"") | M13: =IFERROR(F13*L13,"") | N13: =IFERROR(J13*L13,"") | O13: ADDED (was missing): one control per pool. [no catalog price] | P13: =IFERROR(IF(LEFT(D13,1)="K",VLOOKUP(D13,Kit_Catalog!$A:$K,8,FALSE()),VLOOKUP(D13,Additional_Supply_Catalog!$A:$K,7,FALSE())),"") | Q13: =IFERROR(IF(LEFT(D13,1)="K",VLOOKUP(D13,Kit_Catalog!$A:$K,7,FALSE()),VLOOKUP(D13,Additional_Supply_Catalog!$A:$K,8,FALSE())),"") | R13: =IFERROR(IF(LEFT(D13,1)="K","rxn",VLOOKUP(D13,Additional_Supply_Catalog!$A:$K,9,FALSE())),"")
A14: III. Unsort CITE-seq stain | B14: BUFFER ▸ prepare | C14: Staining buffer (PBS+2% BSA) | E14: (prep total) | G14: mL | J14: =(14*Inputs!$B$6 + 3.1*Inputs!$B$7)*(1+Inputs!$B$20) -> 95.81 | O14: Standard-recipe volume to prepare; costed components are the item rows below (see Buffer recipes).
A15: III. Unsort CITE-seq stain | B15: Item | C15: 2mL eppendorf | D15: S005 | E15: per genetic pool | F15: 1 | G15: each | H15: =Inputs!$B$20 -> 0.1 | I15: =VLOOKUP(E15,Inputs!$D$5:$E$23,2,FALSE()) -> 6 | J15: =F15*I15*(1+H15) -> 6.6 | K15: =IF(ISNUMBER(MATCH(G15,{"tube","each","plate","vial","kit","bottle","aliquot","strainer","cap","lane-rxn","tip","strip","lane","channel","library","sample"},0)),ROUNDUP(J15,0),ROUND(J15,2)) -> 7 | L15: =IFERROR(IF(OR(D15="",P15="",Q15="",Q15=0),"",IF(VLOOKUP(R15,Unit_Conversions!$A$5:$C$28,3,FALSE())=VLOOKUP(G15,Unit_Conversions!$A$5:$C$28,3,FALSE()),P15*VLOOKUP(G15,Unit_Conversions!$A$5:$C$28,2,FALSE())/(Q15*VLOOKUP(R15,Unit_Conversions!$A$5:$C$28,2,FALSE())),"")),"") -> 0.17956 | M15: =IFERROR(F15*L15,"") -> 0.17956 | N15: =IFERROR(J15*L15,"") -> 1.185096 | P15: =IFERROR(IF(LEFT(D15,1)="K",VLOOKUP(D15,Kit_Catalog!$A:$K,8,FALSE()),VLOOKUP(D15,Additional_Supply_Catalog!$A:$K,7,FALSE())),"") -> 44.89 | Q15: =IFERROR(IF(LEFT(D15,1)="K",VLOOKUP(D15,Kit_Catalog!$A:$K,7,FALSE()),VLOOKUP(D15,Additional_Supply_Catalog!$A:$K,8,FALSE())),"") -> 250 | R15: =IFERROR(IF(LEFT(D15,1)="K","rxn",VLOOKUP(D15,Additional_Supply_Catalog!$A:$K,9,FALSE())),"") -> tube
A16: III. Unsort CITE-seq stain | B16: Item | C16: 50mL conical | D16: S007 | E16: per genetic pool | F16: 1 | G16: tube | H16: =Inputs!$B$20 -> 0.1 | I16: =VLOOKUP(E16,Inputs!$D$5:$E$23,2,FALSE()) -> 6 | J16: =F16*I16*(1+H16) -> 6.6 | K16: =IF(ISNUMBER(MATCH(G16,{"tube","each","plate","vial","kit","bottle","aliquot","strainer","cap","lane-rxn","tip","strip","lane","channel","library","sample"},0)),ROUNDUP(J16,0),ROUND(J16,2)) -> 7 | L16: =IFERROR(IF(OR(D16="",P16="",Q16="",Q16=0),"",IF(VLOOKUP(R16,Unit_Conversions!$A$5:$C$28,3,FALSE())=VLOOKUP(G16,Unit_Conversions!$A$5:$C$28,3,FALSE()),P16*VLOOKUP(G16,Unit_Conversions!$A$5:$C$28,2,FALSE())/(Q16*VLOOKUP(R16,Unit_Conversions!$A$5:$C$28,2,FALSE())),"")),"") -> 0.244 | M16: =IFERROR(F16*L16,"") -> 0.244 | N16: =IFERROR(J16*L16,"") -> 1.6104 | O16: [no catalog price] | P16: =IFERROR(IF(LEFT(D16,1)="K",VLOOKUP(D16,Kit_Catalog!$A:$K,8,FALSE()),VLOOKUP(D16,Additional_Supply_Catalog!$A:$K,7,FALSE())),"") -> 6.1 | Q16: =IFERROR(IF(LEFT(D16,1)="K",VLOOKUP(D16,Kit_Catalog!$A:$K,7,FALSE()),VLOOKUP(D16,Additional_Supply_Catalog!$A:$K,8,FALSE())),"") -> 25 | R16: =IFERROR(IF(LEFT(D16,1)="K","rxn",VLOOKUP(D16,Additional_Supply_Catalog!$A:$K,9,FALSE())),"") -> tube
A17: III. Unsort CITE-seq stain | B17: Item | C17: 40um Flowmi Strainer | D17: S011 | E17: per genetic pool | F17: 1 | G17: sample | H17: =Inputs!$B$20 -> 0.1 | I17: =VLOOKUP(E17,Inputs!$D$5:$E$23,2,FALSE()) -> 6 | J17: =F17*I17*(1+H17) -> 6.6 | K17: =IF(ISNUMBER(MATCH(G17,{"tube","each","plate","vial","kit","bottle","aliquot","strainer","cap","lane-rxn","tip","strip","lane","channel","library","sample"},0)),ROUNDUP(J17,0),ROUND(J17,2)) -> 7 | L17: =IFERROR(IF(OR(D17="",P17="",Q17="",Q17=0),"",IF(VLOOKUP(R17,Unit_Conversions!$A$5:$C$28,3,FALSE())=VLOOKUP(G17,Unit_Conversions!$A$5:$C$28,3,FALSE()),P17*VLOOKUP(G17,Unit_Conversions!$A$5:$C$28,2,FALSE())/(Q17*VLOOKUP(R17,Unit_Conversions!$A$5:$C$28,2,FALSE())),"")),"") -> 2.28 | M17: =IFERROR(F17*L17,"") -> 2.28 | N17: =IFERROR(J17*L17,"") -> 15.048 | P17: =IFERROR(IF(LEFT(D17,1)="K",VLOOKUP(D17,Kit_Catalog!$A:$K,8,FALSE()),VLOOKUP(D17,Additional_Supply_Catalog!$A:$K,7,FALSE())),"") -> 114 | Q17: =IFERROR(IF(LEFT(D17,1)="K",VLOOKUP(D17,Kit_Catalog!$A:$K,7,FALSE()),VLOOKUP(D17,Additional_Supply_Catalog!$A:$K,8,FALSE())),"") -> 50 | R17: =IFERROR(IF(LEFT(D17,1)="K","rxn",VLOOKUP(D17,Additional_Supply_Catalog!$A:$K,9,FALSE())),"") -> each
A18: III. Unsort CITE-seq stain | B18: Item | C18: 5mL FACS tube | D18: S013 | E18: per genetic pool | F18: 1 | G18: tube | H18: =Inputs!$B$20 -> 0.1 | I18: =VLOOKUP(E18,Inputs!$D$5:$E$23,2,FALSE()) -> 6 | J18: =F18*I18*(1+H18) -> 6.6 | K18: =IF(ISNUMBER(MATCH(G18,{"tube","each","plate","vial","kit","bottle","aliquot","strainer","cap","lane-rxn","tip","strip","lane","channel","library","sample"},0)),ROUNDUP(J18,0),ROUND(J18,2)) -> 7 | L18: =IFERROR(IF(OR(D18="",P18="",Q18="",Q18=0),"",IF(VLOOKUP(R18,Unit_Conversions!$A$5:$C$28,3,FALSE())=VLOOKUP(G18,Unit_Conversions!$A$5:$C$28,3,FALSE()),P18*VLOOKUP(G18,Unit_Conversions!$A$5:$C$28,2,FALSE())/(Q18*VLOOKUP(R18,Unit_Conversions!$A$5:$C$28,2,FALSE())),"")),"") | M18: =IFERROR(F18*L18,"") | N18: =IFERROR(J18*L18,"") | O18: [no catalog price] | P18: =IFERROR(IF(LEFT(D18,1)="K",VLOOKUP(D18,Kit_Catalog!$A:$K,8,FALSE()),VLOOKUP(D18,Additional_Supply_Catalog!$A:$K,7,FALSE())),"") -> 19.16 | Q18: =IFERROR(IF(LEFT(D18,1)="K",VLOOKUP(D18,Kit_Catalog!$A:$K,7,FALSE()),VLOOKUP(D18,Additional_Supply_Catalog!$A:$K,8,FALSE())),"") -> 12 | R18: =IFERROR(IF(LEFT(D18,1)="K","rxn",VLOOKUP(D18,Additional_Supply_Catalog!$A:$K,9,FALSE())),"") -> 0
A19: III. Unsort CITE-seq stain | B19: Item | C19: TotalseqC HTO | D19: R018 | E19: per genetic pool | F19: 2 | G19: uL | H19: =Inputs!$B$20 -> 0.1 | I19: =VLOOKUP(E19,Inputs!$D$5:$E$23,2,FALSE()) -> 6 | J19: =F19*I19*(1+H19) -> 13.2 | K19: =IF(ISNUMBER(MATCH(G19,{"tube","each","plate","vial","kit","bottle","aliquot","strainer","cap","lane-rxn","tip","strip","lane","channel","library","sample"},0)),ROUNDUP(J19,0),ROUND(J19,2)) -> 13.2 | L19: =IFERROR(IF(OR(D19="",P19="",Q19="",Q19=0),"",IF(VLOOKUP(R19,Unit_Conversions!$A$5:$C$28,3,FALSE())=VLOOKUP(G19,Unit_Conversions!$A$5:$C$28,3,FALSE()),P19*VLOOKUP(G19,Unit_Conversions!$A$5:$C$28,2,FALSE())/(Q19*VLOOKUP(R19,Unit_Conversions!$A$5:$C$28,2,FALSE())),"")),"") -> 25.85 | M19: =IFERROR(F19*L19,"") -> 51.7 | N19: =IFERROR(J19*L19,"") -> 341.22 | P19: =IFERROR(IF(LEFT(D19,1)="K",VLOOKUP(D19,Kit_Catalog!$A:$K,8,FALSE()),VLOOKUP(D19,Additional_Supply_Catalog!$A:$K,7,FALSE())),"") -> 517 | Q19: =IFERROR(IF(LEFT(D19,1)="K",VLOOKUP(D19,Kit_Catalog!$A:$K,7,FALSE()),VLOOKUP(D19,Additional_Supply_Catalog!$A:$K,8,FALSE())),"") -> 20 | R19: =IFERROR(IF(LEFT(D19,1)="K","rxn",VLOOKUP(D19,Additional_Supply_Catalog!$A:$K,9,FALSE())),"") -> uL
